Workbook

Sheet LEIA-ME
A1: Rumo – Base de conhecimento oficial (v3)
A2: Escopo: capital de São Paulo. Fluxos: CPF, autorização de residência (Venezuela/Guiana/Suriname, Mercosul, reunião familiar), registro e CRNM, refúgio, comprovante de residência. Verificação feita em 28/10/2026.
A4: Como ler
A5: Países | B5: O usuário escolhe o país manualmente. Esta aba diz quais modalidades a PF oferece para cada nacionalidade e qual fluxo do app usar.
A6: Procedimentos | B6: Uma linha por procedimento: órgão, quem pode pedir, canal, custo, prazo, base legal e fontes.
A7: Documentos | B7: Cada documento ligado a um procedimento, com status, condição, alternativas e fonte.
A8: Etapas | B8: Passo a passo de cada procedimento, com link oficial.
A9: Taxas | B9: Valores oficiais e isenções.
A10: Locais SP | B10: Onde ir, separando quem processa pedidos de quem só orienta.
A11: Explicações | B11: Textos curtos que o app mostra (ex.: o que é o CPF), cada um com status e fonte. Só os confirmados aparecem no app.
A12: Fontes | B12: Todas as fontes, com data de atualização da página e se estava acessível.
A14: Status dos documentos
A15: Obrigatório | B15: A fonte oficial exige o documento para aquela situação.
A16: Condicional | B16: Só é exigido em certas situações (coluna Condição).
A17: A confirmar | B17: Não foi possível confirmar em fonte oficial acessível. O app deve mostrar 'confirme no canal oficial' e nunca apresentar como certo.
A19: Cores
A20: Fundo amarelo | B20: Linha com algo a confirmar, parcial, fonte restrita ou fora do MVP. São os itens para o revisor jurídico.
A22: Como editar | B22: Para adicionar um documento, copie uma linha existente da aba Documentos (ex.: a primeira linha de P-CPF) e troque os campos. Toda linha precisa de um process_id que exista em Procedimentos e de uma fonte que exista em Fontes. O resumo abaixo se atualiza sozinho.
A24: Resumo por procedimento (calculado)
A25: Procedimento | B25: Obrigatório | C25: Condicional | D25: A confirmar | E25: Total de documentos | F25: % confirmado
A26: P-CPF | B26: =COUNTIFS(Documentos!$B$2:$B$55,$A26,Documentos!$D$2:$D$55,"Obrigatório") -> 1 | C26: =COUNTIFS(Documentos!$B$2:$B$55,$A26,Documentos!$D$2:$D$55,"Condicional") -> 2 | D26: =COUNTIFS(Documentos!$B$2:$B$55,$A26,Documentos!$D$2:$D$55,"A confirmar") -> 1 | E26: =COUNTIF(Documentos!$B$2:$B$55,$A26) -> 4 | F26: =IF(E26=0,0,(B26+C26)/E26) -> 0.75
A27: P-RES-VEN | B27: =COUNTIFS(Documentos!$B$2:$B$55,$A27,Documentos!$D$2:$D$55,"Obrigatório") -> 3 | C27: =COUNTIFS(Documentos!$B$2:$B$55,$A27,Documentos!$D$2:$D$55,"Condicional") -> 7 | D27: =COUNTIFS(Documentos!$B$2:$B$55,$A27,Documentos!$D$2:$D$55,"A confirmar") -> 1 | E27: =COUNTIF(Documentos!$B$2:$B$55,$A27) -> 11 | F27: =IF(E27=0,0,(B27+C27)/E27) -> 0.90909091
A28: P-RES-MERCOSUL | B28: =COUNTIFS(Documentos!$B$2:$B$55,$A28,Documentos!$D$2:$D$55,"Obrigatório") -> 4 | C28: =COUNTIFS(Documentos!$B$2:$B$55,$A28,Documentos!$D$2:$D$55,"Condicional") -> 2 | D28: =COUNTIFS(Documentos!$B$2:$B$55,$A28,Documentos!$D$2:$D$55,"A confirmar") -> 4 | E28: =COUNTIF(Documentos!$B$2:$B$55,$A28) -> 10 | F28: =IF(E28=0,0,(B28+C28)/E28) -> 0.6
A29: P-RES-REUNIAO | B29: =COUNTIFS(Documentos!$B$2:$B$55,$A29,Documentos!$D$2:$D$55,"Obrigatório") -> 7 | C29: =COUNTIFS(Documentos!$B$2:$B$55,$A29,Documentos!$D$2:$D$55,"Condicional") -> 3 | D29: =COUNTIFS(Documentos!$B$2:$B$55,$A29,Documentos!$D$2:$D$55,"A confirmar") -> 1 | E29: =COUNTIF(Documentos!$B$2:$B$55,$A29) -> 11 | F29: =IF(E29=0,0,(B29+C29)/E29) -> 0.90909091
A30: P-REG-CRNM | B30: =COUNTIFS(Documentos!$B$2:$B$55,$A30,Documentos!$D$2:$D$55,"Obrigatório") -> 2 | C30: =COUNTIFS(Documentos!$B$2:$B$55,$A30,Documentos!$D$2:$D$55,"Condicional") -> 0 | D30: =COUNTIFS(Documentos!$B$2:$B$55,$A30,Documentos!$D$2:$D$55,"A confirmar") -> 1 | E30: =COUNTIF(Documentos!$B$2:$B$55,$A30) -> 3 | F30: =IF(E30=0,0,(B30+C30)/E30) -> 0.66666667
A31: P-REFUGIO | B31: =COUNTIFS(Documentos!$B$2:$B$55,$A31,Documentos!$D$2:$D$55,"Obrigatório") -> 3 | C31: =COUNTIFS(Documentos!$B$2:$B$55,$A31,Documentos!$D$2:$D$55,"Condicional") -> 1 | D31: =COUNTIFS(Documentos!$B$2:$B$55,$A31,Documentos!$D$2:$D$55,"A confirmar") -> 0 | E31: =COUNTIF(Documentos!$B$2:$B$55,$A31) -> 4 | F31: =IF(E31=0,0,(B31+C31)/E31) -> 1
A32: P-DPRNM | B32: =COUNTIFS(Documentos!$B$2:$B$55,$A32,Documentos!$D$2:$D$55,"Obrigatório") -> 2 | C32: =COUNTIFS(Documentos!$B$2:$B$55,$A32,Documentos!$D$2:$D$55,"Condicional") -> 2 | D32: =COUNTIFS(Documentos!$B$2:$B$55,$A32,Documentos!$D$2:$D$55,"A confirmar") -> 0 | E32: =COUNTIF(Documentos!$B$2:$B$55,$A32) -> 4 | F32: =IF(E32=0,0,(B32+C32)/E32) -> 1
A33: P-ENDERECO | B33: =COUNTIFS(Documentos!$B$2:$B$55,$A33,Documentos!$D$2:$D$55,"Obrigatório") -> 2 | C33: =COUNTIFS(Documentos!$B$2:$B$55,$A33,Documentos!$D$2:$D$55,"Condicional") -> 0 | D33: =COUNTIFS(Documentos!$B$2:$B$55,$A33,Documentos!$D$2:$D$55,"A confirmar") -> 0 | E33: =COUNTIF(Documentos!$B$2:$B$55,$A33) -> 2 | F33: =IF(E33=0,0,(B33+C33)/E33) -> 1
A34: P-COMPROVANTE | B34: =COUNTIFS(Documentos!$B$2:$B$55,$A34,Documentos!$D$2:$D$55,"Obrigatório") -> 0 | C34: =COUNTIFS(Documentos!$B$2:$B$55,$A34,Documentos!$D$2:$D$55,"Condicional") -> 2 | D34: =COUNTIFS(Documentos!$B$2:$B$55,$A34,Documentos!$D$2:$D$55,"A confirmar") -> 3 | E34: =COUNTIF(Documentos!$B$2:$B$55,$A34) -> 5 | F34: =IF(E34=0,0,(B34+C34)/E34) -> 0.4
A35: Total | B35: =SUM(B26:B34) -> 24 | C35: =SUM(C26:C34) -> 19 | D35: =SUM(D26:D34) -> 11 | E35: =SUM(E26:E34) -> 54 | F35: =IF(E35=0,0,(B35+C35)/E35) -> 0.7962963
A37: Fontes oficiais restritas (exigiam login) | B37: =COUNTIF(Fontes!$G$2:$G$24,"Restrita*") -> 2
A38: Fontes secundárias (não oficiais) | B38: =COUNTIF(Fontes!$E$2:$E$24,"Secundária*") -> 2

Sheet Países
A1: País | B1: Grupo | C1: Modalidades de residência listadas pela PF (S09) | D1: Fluxo do app (MVP) | E1: Idioma sugerido | F1: Observação
A2: Argentina | B2: Mercosul | C2: Acordo Mercosul; Acordo Brasil/Argentina; Fronteiriço | D2: P-RES-MERCOSUL | E2: Español | F2: Acordo bilateral Brasil/Argentina fora do MVP
A3: Bolívia | B3: Mercosul | C3: Acordo Mercosul; Fronteiriço | D3: P-RES-MERCOSUL | E3: Español
A4: Chile | B4: Mercosul | C4: Acordo Mercosul | D4: P-RES-MERCOSUL | E4: Español
A5: Colômbia | B5: Mercosul | C5: Acordo Mercosul | D5: P-RES-MERCOSUL | E5: Español
A6: Equador | B6: Mercosul | C6: Acordo Mercosul | D6: P-RES-MERCOSUL | E6: Español
A7: Paraguai | B7: Mercosul | C7: Acordo Mercosul | D7: P-RES-MERCOSUL | E7: Español
A8: Peru | B8: Mercosul | C8: Acordo Mercosul | D8: P-RES-MERCOSUL | E8: Español
A9: Uruguai | B9: Mercosul | C9: Acordo Mercosul; Acordo Brasil/Uruguai; Fronteiriço | D9: P-RES-MERCOSUL | E9: Español | F9: Acordo bilateral Brasil/Uruguai fora do MVP
A10: Venezuela | B10: Fronteiriço sem acordo Mercosul | C10: Residência para Venezuela, Suriname e Guiana | D10: P-RES-VEN | E10: Español | F10: Maior grupo de imigrantes no Brasil
A11: Guiana | B11: Fronteiriço sem acordo Mercosul | C11: Residência para Venezuela, Suriname e Guiana; Fronteiriço | D11: P-RES-VEN | E11: English
A12: Suriname | B12: Fronteiriço sem acordo Mercosul | C12: Residência para Venezuela, Suriname e Guiana | D12: P-RES-VEN | E12: English | F12: Neerlandês fora do MVP
A13: Haiti | B13: Acolhida humanitária | C13: Cidadãos do Haiti | D13: FORA DO MVP | E13: Kreyòl / Français | F13: Mostrar reunião familiar, refúgio e encaminhamento ao CRAI
A14: Cuba | B14: Caso específico | C14: Cubano que integrou o Mais Médicos | D14: FORA DO MVP | E14: Español | F14: Demais cubanos: reunião familiar ou refúgio
A15: Ucrânia | B15: Acolhida humanitária | C15: Cidadãos da Ucrânia e apátridas afetados pelo conflito | D15: FORA DO MVP | E15: English
A16: Afeganistão | B16: Acolhida humanitária | C16: Acolhida humanitária – Afeganistão | D16: FORA DO MVP | E16: English
A17: Síria | B17: Acolhida humanitária | C17: Acolhida humanitária – Síria (somente prorrogação) | D17: FORA DO MVP | E17: English
A18: Senegal | B18: Caso específico | C18: Senegalês solicitante de refúgio | D18: FORA DO MVP | E18: Français
A19: República Dominicana | B19: Caso específico | C19: Dominicano solicitante de refúgio | D19: FORA DO MVP | E19: Español
A20: Portugal | B20: CPLP | C20: Comunidade de Países de Língua Portuguesa | D20: FORA DO MVP | E20: Português | F20: Página da PF acessível; candidato ao 2º lote
A21: Angola | B21: CPLP | C21: Comunidade de Países de Língua Portuguesa | D21: FORA DO MVP | E21: Português | F21: Candidato ao 2º lote
A22: Cabo Verde | B22: CPLP | C22: Comunidade de Países de Língua Portuguesa | D22: FORA DO MVP | E22: Português | F22: Candidato ao 2º lote
A23: Guiné-Bissau | B23: CPLP | C23: Comunidade de Países de Língua Portuguesa | D23: FORA DO MVP | E23: Português | F23: Candidato ao 2º lote
A24: Moçambique | B24: CPLP | C24: Comunidade de Países de Língua Portuguesa | D24: FORA DO MVP | E24: Português | F24: Candidato ao 2º lote
A25: São Tomé e Príncipe | B25: CPLP | C25: Comunidade de Países de Língua Portuguesa | D25: FORA DO MVP | E25: Português | F25: Candidato ao 2º lote
A26: Timor-Leste | B26: CPLP | C26: Comunidade de Países de Língua Portuguesa | D26: FORA DO MVP | E26: Português | F26: Candidato ao 2º lote
A27: Todas as nacionalidades | B27: Geral | C27: Reunião familiar; criança ou adolescente desacompanhado; vítimas de tráfico ou trabalho escravo; nômade digital; outras | D27: P-RES-REUNIAO, P-REFUGIO, P-CPF | E27: — | F27: Aparecem para qualquer país. Refúgio não é modalidade da S09: vem de S05/S06

Sheet Procedimentos
A1: process_id | B1: Nome | C1: Jurisdição | D1: Órgão | E1: Quem pode usar | F1: Canal | G1: Custo | H1: Prazo / validade | I1: Base legal | J1: Fontes | K1: Status da verificação | L1: Observações | M1: Verificado em
A2: P-CPF | B2: Inscrição no CPF (pessoa estrangeira) | C2: Federal | D2: Receita Federal | E2: Pessoas físicas brasileiras e estrangeiras, residentes e não residentes no Brasil | F2: Online (formulário 'Inscrever Estrangeiro no CPF'); e-mail; unidades da Receita; conveniados (Correios, Banco do Brasil, Caixa, cartórios) | G2: Gratuito na Receita; R$ 7,00 nos conveniados | H2: Cerca de 15 min presencial; cerca de 48 h por e-mail | I2: A confirmar (instrução normativa da Receita) | J2: S01 | K2: Confirmado | L2: CPF é cadastro fiscal: não comprova situação migratória. A página não diz se os conveniados atendem estrangeiros — a confirmar. Regra do app: se a pessoa responde Não ou Não sei à pergunta "Você já tem CPF?", este fluxo entra no caminho automaticamente como etapa 1. | M2: 28/10/2026
A3: P-RES-VEN | B3: Autorização de residência – Venezuela, Guiana e Suriname (código 273; prazo indeterminado: código 299) | C3: Federal | D3: Polícia Federal | E3: Nacionais da Venezuela, Guiana ou Suriname. Crianças e incapazes: pedido por um dos pais ou representante legal | F3: Formulário eletrônico no site da PF + atendimento presencial em unidade da PF (agendar em S20) | G3: R$ 168,13 + R$ 204,77 quando aplicáveis; isenção por declaração de hipossuficiência | H3: Temporária: 2 anos (S15 – confirmar na PF). Prazo indeterminado: pedir nos 90 dias antes do vencimento (S15) | I3: Portaria Interministerial MJSP/MRE nº 19/2021; Decreto nº 9.199/2017 | J3: S10, S15, S08 | K3: Confirmado (documentos); validade a confirmar na PF | L3: Divergência entre fontes oficiais: a página do MJSP (S04) ainda cita as Portarias 9/2018 e 15/2018 e pede foto 3x4. Seguimos a PF (S10), que cita a Portaria 19/2021 e só pede foto se a biometria falhar. | M3: 28/10/2026
A4: P-RES-MERCOSUL | B4: Autorização de residência – Acordo sobre Residência do Mercosul | C4: Federal | D4: Polícia Federal | E4: Nacionais de Argentina, Bolívia, Chile, Colômbia, Equador, Paraguai, Peru e Uruguai (S09) | F4: Formulário eletrônico no site da PF + atendimento presencial (S03) | G4: R$ 168,13 + R$ 204,77 quando aplicáveis (S03, S16); isenção por hipossuficiência (S08) | H4: Temporária: até 2 anos. Permanente: pedir 90 dias antes do vencimento (Decreto 6.975, arts. 4 e 5) | I4: Decreto nº 6.975/2009 (Argentina, Bolívia, Chile, Paraguai, Uruguai). Adesão de Colômbia, Equador e Peru por outro ato: a confirmar | J4: S13, S16, S09 | K4: Parcial: norma confirmada; página da PF restrita; lista operacional a confirmar | L4: A página da PF (S11) exigia login em 28/10/2026. Lista operacional vem de guia universitário (S16). | M4: 28/10/2026
A5: P-RES-REUNIAO | B5: Autorização de residência – Reunião familiar com brasileiro ou imigrante com autorização de residência | C5: Federal | D5: Polícia Federal | E5: Cônjuge ou companheiro; filho de imigrante com AR; quem tem filho brasileiro ou imigrante com AR; ascendente, descendente até 2º grau ou irmão de brasileiro ou de imigrante com AR; quem tem brasileiro sob tutela ou guarda (Lei 13.445, art. 37) | F5: Formulário eletrônico no site da PF + atendimento presencial (S03, S04) | G5: R$ 168,13 + R$ 204,77 quando aplicáveis (S04); isenção por hipossuficiência (S08) | H5: 130 a 180 dias corridos (estimativa geral da página do MJSP) | I5: Lei nº 13.445/2017, art. 37; Decreto nº 9.199/2017; portaria vinculada pelo MJSP: Portaria Interministerial nº 3/2018 (a confirmar) | J5: S14, S04, S08 | K5: Confirmado no MJSP (S04); página da PF restrita | L5: A página da PF (S12) exigia login em 28/10/2026. Lista de documentos vem do MJSP (S04). | M5: 28/10/2026
A6: P-REG-CRNM | B6: Registro migratório e emissão da CRNM | C6: Federal | D6: Polícia Federal | E6: Imigrantes com visto temporário ou com autorização de residência publicada no DOU; refugiados, apátridas e asilados reconhecidos | F6: Formulário online + GRU; agendamento; atendimento na PF da circunscrição; retirada da CRNM | G6: Taxa de emissão da CRNM R$ 204,77 (STN 140120); demais etapas sem custo | H6: Registrar em 90 dias após a entrada (visto temporário) ou 30 dias após a publicação no DOU (AR). CRNM pronta em média em 30 dias úteis; total até 180 dias | I6: Decreto nº 9.199/2017 (penalidade: art. 307, IV, segundo a FAQ da PF – S08) | J6: S02, S08 | K6: Confirmado (etapas, prazos e taxa); lista de documentos a confirmar | L6: A lista de documentos fica em página da PF que exige login. | M6: 28/10/2026
A7: P-REFUGIO | B7: Solicitação de refúgio (primeira vez) | C7: Federal | D7: MJSP / Conare + Polícia Federal | E7: Pessoas estrangeiras ou apátridas com fundado temor de perseguição (raça, religião, nacionalidade, grupo social, opinião política) ou que deixaram o país por grave e generalizada violação de direitos humanos | F7: Sisconare (cadastro e solicitação) + agendamento na PF + comparecimento presencial | G7: Gratuito | H7: Protocolo de Refúgio válido por 1 ano, renovado na PF até a decisão do Conare. Prazo total estimado: 12 a 24 meses | I7: Lei nº 9.474/1997 | J7: S05, S06 | K7: Confirmado | L7: Consultar o Sisconare ao menos a cada 30 dias. Cada pessoa da família precisa de agendamento próprio. | M7: 28/10/2026
A8: P-DPRNM | B8: Documento Provisório de Registro Nacional Migratório (DPRNM) | C8: Federal | D8: Polícia Federal | E8: Imigrantes que estão pedindo ou renovando o refúgio | F8: Atendimento na PF agendado em 'Solicitar Refúgio' ou 'Renovar Protocolo de Refúgio' | G8: Gratuito | H8: Até 20 dias corridos para ficar pronto | I8: A confirmar | J8: S07 | K8: Confirmado | M8: 28/10/2026
A9: P-ENDERECO | B9: Alteração de endereço no registro migratório | C9: Federal | D9: Polícia Federal | E9: Imigrante registrado que mudou de endereço | F9: Formulário eletrônico no site da PF, sem ir à unidade | G9: Gratuito | H9: — | I9: A confirmar | J9: S08 | K9: Confirmado | M9: 28/10/2026
A10: P-COMPROVANTE | B10: Orientação: comprovante de residência e CEP | C10: Varia por órgão | D10: Depende do serviço de destino | E10: Qualquer pessoa | F10: Não é um procedimento: orientação para obter e conferir documentos | G10: — | H10: — | I10: Não há lista universal | J10: S08, S22 | K10: Orientação | L10: Ter CEP não é ter comprovante. Cada órgão define o que aceita. | M10: 28/10/2026

Sheet Documentos
A1: doc_id | B1: process_id | C1: Documento | D1: Status | E1: Condição (quando se aplica) | F1: Alternativas aceitas | G1: Como obter | H1: Formalidades (tradução / apostila) | I1: Etapa em que é apresentado | J1: Fonte | K1: Observação
A2: D001 | B2: P-CPF | C2: Documento de identificação oficial com foto | D2: Obrigatório | G2: Passaporte ou documento do país de origem; CRNM/DPRNM se já tiver | I2: Pedido | J2: S01
A3: D002 | B3: P-CPF | C3: Certidão de nascimento ou de casamento (ou equivalente estrangeiro) | D3: Condicional | E3: Só se o documento de identificação não mostrar naturalidade, filiação e data de nascimento | G3: Cartório do país de origem ou consulado | H3: A confirmar | I3: Pedido | J3: S01
A4: D003 | B4: P-CPF | C4: Foto segurando o documento ao lado do rosto | D4: Condicional | E4: Só no atendimento por e-mail | F4: Frente e verso se não der para mostrar o documento inteiro | G4: Foto com o celular | I4: Pedido por e-mail | J4: S01
A5: D004 | B5: P-CPF | C5: Outros documentos solicitados pelo atendente | D5: A confirmar | E5: Caso a caso | I5: Atendimento | J5: S01
A6: D005 | B6: P-RES-VEN | C6: Requerimento eletrônico preenchido no site da PF, impresso e assinado | D6: Obrigatório | G6: Site da PF | I6: Atendimento na PF | J6: S10
A7: D006 | B7: P-RES-VEN | C7: Cédula de identidade ou passaporte, ainda que vencido | D7: Obrigatório | F7: Indígena sem cédula, passaporte ou certidão: documento de identificação do país de origem + autodeclaração de filiação (S10) | G7: Documento que a pessoa já tem | I7: Atendimento na PF | J7: S10
A8: D007 | B8: P-RES-VEN | C8: Certidão de nascimento, de casamento ou certidão consular | D8: Condicional | E8: Só se o documento de identidade ou de viagem não trouxer a filiação | F8: Em situação de vulnerabilidade, a PF pode dispensar e a filiação é autodeclarada (S10) | G8: Cartório do país de origem ou consulado | I8: Atendimento na PF | J8: S10
A9: D008 | B9: P-RES-VEN | C9: Declaração de ausência de antecedentes criminais no Brasil e no exterior (últimos 5 anos) | D9: Obrigatório | E9: Dispensada para menores de 18 anos | G9: Modelo de declaração da PF | I9: Atendimento na PF | J9: S10
A10: D009 | B10: P-RES-VEN | C10: Comprovantes de pagamento das taxas | D10: Condicional | E10: Quando aplicáveis | F10: Declaração de hipossuficiência econômica (S08) | G10: GRU emitida pelo link da PF | I10: Pedido | J10: S10, S08
A11: D010 | B11: P-RES-VEN | C11: Foto 3x4 recente, colorida, fundo branco | D11: Condicional | E11: Só se o sistema biométrico estiver indisponível | G11: Estúdio de foto | I11: Atendimento na PF | J11: S10
A12: D011 | B12: P-RES-VEN | C12: Declaração de meios de contato | D12: A confirmar | I12: Atendimento na PF | J12: S15 | K12: Citada pela OIM, não pela página da PF
A13: D012 | B13: P-RES-VEN | C13: CRNM | D13: Condicional | E13: Só para mudar para prazo indeterminado (código 299) | G13: Recebida no primeiro pedido | I13: Mudança de prazo | J13: S10
A14: D013 | B14: P-RES-VEN | C14: Certidões de antecedentes criminais da autoridade judicial do local de residência temporária | D14: Condicional | E14: Só para prazo indeterminado (código 299) | G14: Justiça Estadual e Federal (S15) | I14: Mudança de prazo | J14: S10, S15
A15: D014 | B15: P-RES-VEN | C15: Declaração de ausência de registros criminais no Brasil | D15: Condicional | E15: Só para prazo indeterminado; dispensada para menores de 18 | G15: Modelo de declaração da PF | I15: Mudança de prazo | J15: S10
A16: D015 | B16: P-RES-VEN | C16: Comprovação de meios de subsistência | D16: Condicional | E16: Só para prazo indeterminado | G16: Ver dúvidas frequentes da PF | I16: Mudança de prazo | J16: S10
A17: D016 | B17: P-RES-MERCOSUL | C17: Passaporte, carteira de identidade ou certidão de nacionalidade | D17: Obrigatório | G17: Documento do país de origem ou consulado | I17: Atendimento na PF | J17: S13 (art. 4a)
A18: D017 | B18: P-RES-MERCOSUL | C18: Certidão de nascimento e comprovação de estado civil; certificado de naturalização quando aplicável | D18: Obrigatório | E18: Naturalização: só se a pessoa for naturalizada | G18: Cartório do país de origem ou consulado | H18: A confirmar: acordos Mercosul podem dispensar legalização/tradução (S08) | I18: Atendimento na PF | J18: S13 (art. 4b)
A19: D018 | B19: P-RES-MERCOSUL | C19: Certidão negativa de antecedentes judiciais, penais ou policiais do país de origem ou de onde morou nos últimos 5 anos | D19: Obrigatório | F19: A PF pode aceitar certidão com mais de 90 dias (S16) | G19: Órgão policial ou judicial do país | H19: A confirmar: acordos Mercosul podem dispensar legalização/tradução (S08) | I19: Atendimento na PF | J19: S13 (art. 4c)
A20: D019 | B20: P-RES-MERCOSUL | C20: Declaração, sob as penas da lei, de ausência de antecedentes penais ou policiais internacionais | D20: Obrigatório | G20: Modelo de declaração da PF | I20: Atendimento na PF | J20: S13 (art. 4d)
A21: D020 | B21: P-RES-MERCOSUL | C21: Certidão de antecedentes no Brasil | D21: Condicional | E21: Para quem já está no Brasil (art. 3º, §2) | G21: Justiça Estadual e Federal | I21: Atendimento na PF | J21: S13 (art. 4e)
A22: D021 | B22: P-RES-MERCOSUL | C22: Atestado médico de aptidão psicofísica | D22: A confirmar | E22: Só se exigido pela legislação interna | I22: — | J22: S13 (art. 4f) | K22: Não aparece na lista operacional S16
A23: D022 | B23: P-RES-MERCOSUL | C23: Comprovante de pagamento das taxas | D23: Condicional | E23: Quando aplicáveis | F23: Declaração de hipossuficiência econômica (S08) | G23: GRU | I23: Pedido | J23: S13 (art. 4g), S16
A24: D023 | B24: P-RES-MERCOSUL | C24: Formulário de solicitação preenchido | D24: A confirmar | G24: Site da PF | I24: Pedido | J24: S16 | K24: Página da PF restrita
A25: D024 | B25: P-RES-MERCOSUL | C25: Duas fotos 3x4 | D25: A confirmar | I25: Atendimento na PF | J25: S16 | K25: Na modalidade Venezuela a foto só é pedida se a biometria falhar
A26: D025 | B26: P-RES-MERCOSUL | C26: Declaração de endereço eletrônico e meios de contato | D26: A confirmar | I26: Atendimento na PF | J26: S16
A27: D026 | B27: P-RES-REUNIAO | C27: Formulário de solicitação preenchido | D27: Obrigatório | G27: Site da PF | I27: Pedido | J27: S04
A28: D027 | B28: P-RES-REUNIAO | C28: Documento de viagem ou documento oficial de identidade | D28: Obrigatório | G28: Documento que a pessoa já tem | I28: Atendimento na PF | J28: S04
A29: D028 | B29: P-RES-REUNIAO | C29: Duas fotos 3x4 | D29: A confirmar | G29: Estúdio de foto | I29: Atendimento na PF | J29: S04 | K29: O MJSP pede; em outras modalidades a PF só pede foto se a biometria falhar
A30: D029 | B30: P-RES-REUNIAO | C30: Certidão de nascimento, de casamento ou consular | D30: Condicional | E30: Só se o documento de identidade não trouxer a filiação | G30: Cartório do país de origem ou consulado | H30: Documento estrangeiro: tradução juramentada e apostila ou legalização, salvo acordo (S08) | I30: Atendimento na PF | J30: S04, S08
A31: D030 | B31: P-RES-REUNIAO | C31: Certidões de antecedentes criminais de onde morou nos últimos 5 anos | D31: Obrigatório | G31: Autoridade judicial ou policial de cada país | H31: Documento estrangeiro: tradução juramentada e apostila ou legalização, salvo acordo (S08) | I31: Atendimento na PF | J31: S04, S08
A32: D031 | B32: P-RES-REUNIAO | C32: Declaração de ausência de antecedentes criminais em qualquer país nos últimos 5 anos | D32: Obrigatório | G32: Modelo de declaração da PF | I32: Atendimento na PF | J32: S04
A33: D032 | B33: P-RES-REUNIAO | C33: Certidão de nascimento ou casamento que prove o parentesco, ou outro documento que comprove o vínculo | D33: Obrigatório | E33: Depende do vínculo (Lei 13.445, art. 37) | F33: Outro documento hábil que comprove o vínculo | G33: Cartório brasileiro ou do país de origem | H33: Documento estrangeiro: tradução juramentada e apostila ou legalização, salvo acordo (S08) | I33: Atendimento na PF | J33: S04, S14, S08
A34: D033 | B34: P-RES-REUNIAO | C34: Documento de identidade do familiar chamante (brasileiro ou imigrante com autorização de residência) | D34: Obrigatório | G34: Cópia do documento do familiar | I34: Atendimento na PF | J34: S04
A35: D034 | B35: P-RES-REUNIAO | C35: Declaração de que o familiar chamante mora no Brasil | D35: Obrigatório | G35: Declaração sob as penas da lei | I35: Atendimento na PF | J35: S04
A36: D035 | B36: P-RES-REUNIAO | C36: Comprovante de dependência econômica | D36: Condicional | E36: Só para irmão maior de 18 anos | I36: Atendimento na PF | J36: S04
A37: D036 | B37: P-RES-REUNIAO | C37: Comprovante de pagamento das taxas | D37: Condicional | E37: Quando aplicáveis | F37: Declaração de hipossuficiência econômica (S08) | G37: GRU gerada no site da PF | I37: Pedido | J37: S04, S08
A38: D037 | B38: P-REG-CRNM | C38: Comprovante de pagamento da taxa de emissão da CRNM (STN 140120) | D38: Obrigatório | F38: Declaração de hipossuficiência econômica (S08) | G38: GRU gerada no site da PF; pagamento pelo PagTesouro (S03) | I38: Pedido | J38: S02, S03, S08
A39: D038 | B39: P-REG-CRNM | C39: Documento de identificação | D39: Obrigatório | F39: RG, CIN, CNH, passaporte, RNM ou DPRNM (lista da PF para coleta biométrica) | G39: Documento que a pessoa já tem | I39: Atendimento na PF | J39: S08
A40: D039 | B40: P-REG-CRNM | C40: Demais documentos da lista da PF | D40: A confirmar | I40: Atendimento na PF | J40: S02 | K40: Lista em página que exige login
...

Sheet Etapas
A1: process_id | B1: Nº | C1: Etapa | D1: Canal / link oficial | E1: Tempo estimado | F1: Custo | G1: Fonte
A2: P-CPF | B2: 1 | C2: Escolher o canal: online, e-mail, unidade da Receita ou conveniado | D2: https://www.gov.br/pt-br/servicos/inscrever-no-cpf | E2: — | F2: Gratuito / R$ 7,00 conveniado | G2: S01
A3: P-CPF | B3: 2 | C3: Apresentar ou enviar os documentos | D3: — | E3: Média de 2 dias úteis | F3: — | G3: S01
A4: P-CPF | B4: 3 | C4: Receber o número e consultar a situação cadastral | D4: — | E4: — | F4: — | G4: S01
A5: P-RES-VEN | B5: 1 | C5: Preencher o formulário da modalidade no site da PF e gerar a GRU (ou declarar hipossuficiência) | D5: https://www.gov.br/pt-br/servicos/obter-autorizacao-de-residencia-e-carteira-de-registro-migratorio | E5: 20 min | F5: R$ 168,13 + R$ 204,77 | G5: S03, S10
A6: P-RES-VEN | B6: 2 | C6: Agendar atendimento na PF | D6: https://servicos.pf.gov.br/agenda-web/acessar | E6: 20 min | F6: Gratuito | G6: S03, S20
A7: P-RES-VEN | B7: 3 | C7: Comparecer à PF com os originais: coleta de biometria e conferência | D7: — | E7: 30 min + espera até 30 min | F7: Gratuito | G7: S03, S15
A8: P-RES-VEN | B8: 4 | C8: Receber protocolo e número do RNM; acompanhar a CRNM online | D8: https://servicos.pf.gov.br/sismigra-internet/faces/restrito/atendimento/pesquisarRequerimento.seam | E8: Média 30 dias úteis | F8: Gratuito | G8: S03, S21
A9: P-RES-VEN | B9: 5 | C9: Ao chegar à cidade de destino, atualizar o endereço no site da PF | D9: — | E9: — | F9: Gratuito | G9: S15, S08
A10: P-RES-MERCOSUL | B10: 1 | C10: Preencher o formulário no site da PF e gerar a GRU (ou declarar hipossuficiência) | D10: https://www.gov.br/pt-br/servicos/obter-autorizacao-de-residencia-e-carteira-de-registro-migratorio | E10: 20 min | F10: R$ 168,13 + R$ 204,77 | G10: S03
A11: P-RES-MERCOSUL | B11: 2 | C11: Agendar atendimento na PF | D11: https://servicos.pf.gov.br/agenda-web/acessar | E11: 20 min | F11: Gratuito | G11: S03
A12: P-RES-MERCOSUL | B12: 3 | C12: Comparecer à PF da circunscrição do domicílio | D12: — | E12: 30 min + espera até 30 min | F12: Gratuito | G12: S03
A13: P-RES-MERCOSUL | B13: 4 | C13: Retirar a CRNM quando o sistema avisar | D13: — | E13: Média 30 dias úteis | F13: Gratuito | G13: S03
... A32: P-ENDERECO | B32: 2 | C32: Anexar o comprovante de endereço (com CEP) | D32: — | E32: — | F32: Gratuito | G32: S08

Sheet Taxas
A1: Código STN | B1: Taxa | C1: Valor (R$) | D1: Quando se aplica | E1: Isenção | F1: Fonte
A2: 140066 | B2: Processamento e avaliação de pedido de autorização de residência | C2: 168.13 | D2: Pedidos de autorização de residência, quando aplicável | E2: Declaração de hipossuficiência (Decreto 9.199, art. 312; Lei 13.445, art. 4º, XII) | F2: S03, S08, S14
A3: 140120 | B3: Emissão da Carteira de Registro Nacional Migratório (CRNM) | C3: 204.77 | D3: Registro e emissão da CRNM | E3: Declaração de hipossuficiência (idem) | F3: S02, S03, S08, S14
A4: — | B4: Inscrição no CPF em unidade conveniada | C4: 7 | D4: Só em Correios, Banco do Brasil, Caixa ou cartórios | E4: Gratuito na Receita Federal | F4: S01
A5: — | B5: Solicitação de refúgio | C5: 0 | D5: Sempre | E5: — | F5: S06
A6: — | B6: DPRNM | C6: 0 | D6: Sempre | E6: — | F6: S07
A7: — | B7: Alteração de endereço no registro | C7: 0 | D7: Sempre | E7: — | F7: S08
B9: Total de uma autorização de residência com CRNM (sem isenção) | C9: =C2+C3 -> 372.9
B10: Valores lidos nas páginas oficiais em 28/10/2026.

Sheet Locais SP
A1: id | B1: Nome | C1: Natureza | D1: Função | E1: Endereço | F1: Horário | G1: Telefone | H1: E-mail | I1: Serviços | J1: Agendamento | K1: Fonte | L1: Status | M1: Observação
A2: L01 | B2: Polícia Federal – Delegacia de Migração (DELEMIG), Superintendência em SP | C2: Público federal | D2: Processa pedidos | E2: Rua Hugo D'Antola, 95 – Lapa de Baixo – CEP 05038-090 | F2: Seg. a sex., 8h30–17h30; entrega de CRNM/DPRNM 9h–17h | G2: (11) 3538-5234 | H2: delemig.drex.srsp@pf.gov.br | I2: Registro, autorização de residência, CRNM, refúgio (protocolo) | J2: Sim (agenda-web da PF) | K2: S17 | L2: Confirmado | M2: Urgências: migracao.srsp@pf.gov.br. Passagem comprada não conta como urgência.
A3: L02 | B3: CRAI – Centro de Referência e Atendimento para Imigrantes (Oriana Jara) | C3: Público municipal (Prefeitura de SP) | D3: Orienta e encaminha | E3: Rua Major Diogo, 834 – Bela Vista – CEP 01324-001 | F3: Seg. a sex., 8h–18h (atendimento até 17h) | G3: (11) 2361-5069 | H3: atendimento.crai@sefras.org.br (regularização e agendamentos) | I3: Orientação sobre regularização e documentação, serviço social, orientação jurídica, psicologia, CRAI Móvel | J3: Regularização: agendar por e-mail | K3: S18 | L3: Confirmado | M3: Orientação jurídica da DPU às quartas, de manhã, com agendamento. A página também mostra gestao.crai@sefras.org.br no link do e-mail.
A4: L03 | B4: CIC do Imigrante – Centro de Integração e Cidadania | C4: Público estadual (Secretaria da Justiça e Cidadania) | D4: Orienta e encaminha | E4: Rua Guaianazes, 1112 – Campos Elíseos | F4: A confirmar | G4: (11) 3115-2048 | H4: cicimigrante@justica.sp.gov.br | I4: Assessoria jurídica, atendimento psicológico e social, capacitação, aulas de idiomas, encaminhamento ao trabalho | J4: A confirmar | K4: S19 | L4: Parcial | M4: Endereço novo desde 21/07/2025.
A5: L04 | B5: Defensoria Pública da União (DPU) em São Paulo | C5: Público federal | D5: Orientação jurídica gratuita (assuntos federais: PF, MJSP, refúgio) | E5: Sede: a confirmar | F5: No CRAI: quartas de manhã | G5: — | H5: — | I5: Regularização migratória, refúgio, recursos contra decisões federais | J5: Sim (via CRAI) | K5: S18 | L5: Parcial | M5: Canal confirmado: plantão no CRAI. Sede própria a confirmar.
A6: L05 | B6: Defensoria Pública do Estado de São Paulo | C6: Público estadual | D6: Orientação jurídica gratuita (assuntos estaduais: família, moradia, consumo) | E6: Rua Boa Vista, 150 – Centro (a confirmar) | F6: A confirmar | G6: A confirmar | H6: A confirmar | I6: Questões não federais | J6: A confirmar | K6: — | L6: A confirmar | M6: Endereço vindo da pesquisa inicial, ainda não conferido em fonte oficial.
A7: L06 | B7: Missão Paz | C7: Organização da sociedade civil | D7: Acolhe e orienta | E7: A confirmar | F7: A confirmar | G7: A confirmar | H7: A confirmar | I7: Acolhida, orientação, aulas de português (a confirmar) | J7: A confirmar | K7: — | L7: A confirmar
A8: L07 | B8: Cáritas Arquidiocesana de São Paulo | C8: Organização da sociedade civil | D8: Orienta refugiados e solicitantes | E8: A confirmar | F8: A confirmar | G8: A confirmar | H8: A confirmar | I8: Apoio a refugiados (a confirmar) | J8: A confirmar | K8: — | L8: A confirmar
A9: L08 | B9: CAMI – Centro de Apoio e Pastoral do Migrante | C9: Organização da sociedade civil | D9: Orienta | E9: Alameda Nothmann, 485 – Campos Elíseos (a confirmar) | F9: A confirmar | G9: A confirmar | H9: A confirmar | I9: A confirmar | J9: A confirmar | K9: — | L9: A confirmar | M9: Endereço vindo da pesquisa inicial.
A10: L09 | B10: CDHIC – Centro de Direitos Humanos e Cidadania do Imigrante | C10: Organização da sociedade civil | D10: Orienta | E10: Rua Luís Ferreira, 142 (a confirmar) | F10: A confirmar | G10: A confirmar | H10: A confirmar | I10: A confirmar | J10: A confirmar | K10: — | L10: A confirmar | M10: Endereço vindo da pesquisa inicial.

Sheet Explicações
A1: id | B1: Tema | C1: Texto para o app (pt) | D1: Status | E1: Fonte | F1: Observação
A2: E01 | B2: O que é o CPF | C2: É o número do Cadastro de Pessoas Físicas, da Receita Federal. Brasileiros e estrangeiros podem pedir, morando ou não no Brasil. | D2: Confirmado | E2: S01
A3: E02 | B3: Quanto custa o CPF | C3: É gratuito na Receita Federal, pela internet, por e-mail ou presencialmente. Nos Correios, Banco do Brasil, Caixa e cartórios custa R$ 7,00. | D3: Confirmado | E3: S01
A4: E03 | B4: O que o CPF não faz | C4: O CPF é um cadastro da Receita Federal. Ele não substitui a autorização de residência nem o registro na Polícia Federal. | D4: Confirmado | E4: S01, S03 | F4: Inferência a partir da natureza do cadastro; o revisor jurídico deve validar a redação
A5: E04 | B5: Onde o CPF é pedido: Carteira de Trabalho Digital | C5: Para ter a Carteira de Trabalho Digital, você precisa do número do CPF e de uma conta gov.br. | D5: Confirmado | E5: S23
A6: E05 | B6: Onde o CPF é pedido: conta em banco | C6: — | D6: A confirmar | E6: — | F6: Não encontramos fonte oficial clara para estrangeiros. O app não mostra este item até confirmar.
A7: E06 | B7: Onde o CPF é pedido: linha de celular | C7: — | D7: A confirmar | E7: — | F7: Regra da Anatel para estrangeiros a confirmar. O app não mostra este item até confirmar.

Sheet Fontes
A1: source_id | B1: Órgão / autor | C1: Título | D1: URL | E1: Tipo | F1: Atualização da página | G1: Acesso na verificação | H1: Verificado em
A2: S01 | B2: Receita Federal (gov.br) | C2: Inscrever no CPF | D2: https://www.gov.br/pt-br/servicos/inscrever-no-cpf | E2: Oficial – página de serviço | F2: 08/10/2026 | G2: Acessível | H2: 28/10/2026
A3: S02 | B3: Polícia Federal (gov.br) | C3: Registrar-se como estrangeiro no Brasil | D3: https://www.gov.br/pt-br/servicos/registrar-se-como-estrangeiro-no-brasil | E3: Oficial – página de serviço | F3: 01/09/2026 | G3: Acessível | H3: 28/10/2026
A4: S03 | B4: Polícia Federal (gov.br) | C4: Obter autorização de residência e CRNM | D4: https://www.gov.br/pt-br/servicos/obter-autorizacao-de-residencia-e-carteira-de-registro-migratorio | E4: Oficial – página de serviço | F4: 23/07/2026 | G4: Acessível | H4: 28/10/2026
A5: S04 | B5: MJSP | C5: Autorização de residência (modalidades e órgão de protocolo) | D5: https://www.gov.br/mj/pt-br/assuntos/seus-direitos/migracoes/autorizacao-de-residencia | E5: Oficial – página institucional | F5: 23/07/2026 | G5: Acessível | H5: 28/10/2026
A6: S05 | B6: MJSP | C6: Pedir refúgio (passo a passo Sisconare) | D6: https://www.gov.br/mj/pt-br/assuntos/seus-direitos/refugio/servicos/pedir-refugio | E6: Oficial – página institucional | F6: Sem data na página | G6: Acessível | H6: 28/10/2026
A7: S06 | B7: MJSP / Conare (gov.br) | C7: Solicitar refúgio pela primeira vez | D7: https://www.gov.br/pt-br/servicos/solicitar-refugio | E7: Oficial – página de serviço | F7: 06/08/2026 | G7: Acessível | H7: 28/10/2026
A8: S07 | B8: Polícia Federal (gov.br) | C8: Obter Documento Provisório de RNM (DPRNM) | D8: https://www.gov.br/pt-br/servicos/obter-documento-provisorio-de-registro-nacional-migratorio | E8: Oficial – página de serviço | F8: 24/07/2026 | G8: Acessível | H8: 28/10/2026
A9: S08 | B9: Polícia Federal | C9: Dúvidas frequentes – migração | D9: https://www.gov.br/pf/pt-br/assuntos/imigracao/duvidas-frequentes | E9: Oficial – FAQ | F9: Sem data na página | G9: Acessível | H9: 28/10/2026
A10: S09 | B10: Polícia Federal | C10: Escolha o serviço (seletor por nacionalidade e objetivo) | D10: https://www.gov.br/pf/pt-br/assuntos/imigracao/pt/nacionalidade/objetivo/servico | E10: Oficial – página de serviço | F10: Sem data na página | G10: Acessível | H10: 28/10/2026
A11: S10 | B11: Polícia Federal | C11: AR para nacional de país fronteiriço sem acordo Mercosul (Venezuela, Suriname, Guiana) | D11: https://www.gov.br/pf/pt-br/assuntos/imigracao/autorizacao-residencia/autorizacao-de-residencia-para-nacional-de-pais-fronteirico-onde-nao-esteja-em-vigor-o-acordo-de-residencia-para-nacionais-dos-estados-partes-do-mercosul-e-paises-associados | E11: Oficial – página de serviço | F11: 06/11/2024 | G11: Acessível | H11: 28/10/2026
A12: S11 | B12: Polícia Federal | C12: Acordo sobre Residência do Mercosul (AR) | D12: https://www.gov.br/pf/pt-br/assuntos/imigracao/autorizacao-residencia/acordo-de-residencia-para-nacionais-dos-estados-partes-do-mercosul-bolivia-e-chile | E12: Oficial – página de serviço | F12: Não lida | G12: Restrita (exige login) em 28/10/2026 | H12: 28/10/2026
... A24: S22 | B24: Correios | C24: Consulta de CEP | D24: https://www.correios.com.br/ | E24: Oficial – serviço | F24: — | G24: Não lida nesta rodada | H24: 28/10/2026
